<?xml version="1.0" ?>
<robot name="GP10">
  <link name="base_link">
    <visual>
      <origin xyz="0.0000 0.0000 0.0000" rpy="1.5708 -0.0000 -1.5708"/>
      <geometry>
        <mesh filename="package://GP10/meshes/base_link.stl" scale="0.001 0.001 0.001"/>
      </geometry>
    </visual>
    <collision>
      <origin xyz="0.0000 0.0000 0.0000" rpy="1.5708 -0.0000 -1.5708"/>
      <geometry>
        <mesh filename="package://GP10/meshes/base_link.stl" scale="0.001 0.001 0.001"/>
      </geometry>
    </collision>
  </link>
  <link name="link1">
    <visual>
      <origin xyz="0.0000 0.0000 0.1635" rpy="1.5708 -0.0000 -1.5708"/>
      <geometry>
        <mesh filename="package://GP10/meshes/link1.stl" scale="0.001 0.001 0.001"/>
      </geometry>
    </visual>
    <collision>
      <origin xyz="0.0000 0.0000 0.1635" rpy="1.5708 -0.0000 -1.5708"/>
      <geometry>
        <mesh filename="package://GP10/meshes/link1.stl" scale="0.001 0.001 0.001"/>
      </geometry>
    </collision>
  </link>
  <link name="link2">
    <visual>
      <origin xyz="0.0000 -0.0400 0.3400" rpy="1.5708 -0.0000 -1.5708"/>
      <geometry>
        <mesh filename="package://GP10/meshes/link2.stl" scale="0.001 0.001 0.001"/>
      </geometry>
    </visual>
    <collision>
      <origin xyz="0.0000 -0.0400 0.3400" rpy="1.5708 -0.0000 -1.5708"/>
      <geometry>
        <mesh filename="package://GP10/meshes/link2.stl" scale="0.001 0.001 0.001"/>
      </geometry>
    </collision>
  </link>
  <link name="link3">
    <visual>
      <origin xyz="0.0000 -0.0400 0.8700" rpy="1.5708 -0.0000 -1.5708"/>
      <geometry>
        <mesh filename="package://GP10/meshes/link3.stl" scale="0.001 0.001 0.001"/>
      </geometry>
    </visual>
    <collision>
      <origin xyz="0.0000 -0.0400 0.8700" rpy="1.5708 -0.0000 -1.5708"/>
      <geometry>
        <mesh filename="package://GP10/meshes/link3.stl" scale="0.001 0.001 0.001"/>
      </geometry>
    </collision>
  </link>
  <link name="link4">
    <visual>
      <origin xyz="0.0000 -0.1750 0.9100" rpy="1.5708 -0.0000 -1.5708"/>
      <geometry>
        <mesh filename="package://GP10/meshes/link4.stl" scale="0.001 0.001 0.001"/>
      </geometry>
    </visual>
    <collision>
      <origin xyz="0.0000 -0.1750 0.9100" rpy="1.5708 -0.0000 -1.5708"/>
      <geometry>
        <mesh filename="package://GP10/meshes/link4.stl" scale="0.001 0.001 0.001"/>
      </geometry>
    </collision>
  </link>
  <link name="link5">
    <visual>
      <origin xyz="0.0000 -0.5700 0.9100" rpy="1.5708 -0.0000 -1.5708"/>
      <geometry>
        <mesh filename="package://GP10/meshes/link5.stl" scale="0.001 0.001 0.001"/>
      </geometry>
    </visual>
    <collision>
      <origin xyz="0.0000 -0.5700 0.9100" rpy="1.5708 -0.0000 -1.5708"/>
      <geometry>
        <mesh filename="package://GP10/meshes/link5.stl" scale="0.001 0.001 0.001"/>
      </geometry>
    </collision>
  </link>
  <link name="link6">
    <visual>
      <origin xyz="0.0000 -0.5700 0.8300" rpy="1.5708 -0.0000 -1.5708"/>
      <geometry>
        <mesh filename="package://GP10/meshes/link6.stl" scale="0.001 0.001 0.001"/>
      </geometry>
    </visual>
    <collision>
      <origin xyz="0.0000 -0.5700 0.8300" rpy="1.5708 -0.0000 -1.5708"/>
      <geometry>
        <mesh filename="package://GP10/meshes/link6.stl" scale="0.001 0.001 0.001"/>
      </geometry>
    </collision>
  </link>
  <link name="tool0">
  </link>
  <joint name="joint1" type="revolute">
    <parent link="base_link"/>
    <child link="link1"/>
    <origin xyz="0.0000 0.0000 0.1635" rpy="0.0000 0.0000 0.0000"/>
    <axis xyz="0.000000000000000 0.000000000000000 1.000000000000000"/>
    <limit lower="-3.14159" upper="3.14159" effort="100.0" velocity="1.5"/>
  </joint>
  <joint name="joint2" type="revolute">
    <parent link="link1"/>
    <child link="link2"/>
    <origin xyz="0.0000 -0.0400 0.1765" rpy="0.0000 0.0000 0.0000"/>
    <axis xyz="1.000000000000000 0.000000000000000 0.000000000000000"/>
    <limit lower="-1.74533" upper="2.53073" effort="100.0" velocity="1.5"/>
  </joint>
  <joint name="joint3" type="revolute">
    <parent link="link2"/>
    <child link="link3"/>
    <origin xyz="0.0000 0.0000 0.5300" rpy="0.0000 0.0000 0.0000"/>
    <axis xyz="-1.000000000000000 0.000000000000000 0.000000000000000"/>
    <limit lower="-1.22173" upper="3.31613" effort="100.0" velocity="1.5"/>
  </joint>
  <joint name="joint4" type="revolute">
    <parent link="link3"/>
    <child link="link4"/>
    <origin xyz="0.0000 -0.1350 0.0400" rpy="0.0000 0.0000 0.0000"/>
    <axis xyz="0.000000000000000 -1.000000000000000 0.000000000000000"/>
    <limit lower="-3.31613" upper="3.31613" effort="100.0" velocity="1.5"/>
  </joint>
  <joint name="joint5" type="revolute">
    <parent link="link4"/>
    <child link="link5"/>
    <origin xyz="0.0000 -0.3950 0.0000" rpy="0.0000 0.0000 0.0000"/>
    <axis xyz="-1.000000000000000 0.000000000000000 0.000000000000000"/>
    <limit lower="-0.78540" upper="3.92699" effort="100.0" velocity="1.5"/>
  </joint>
  <joint name="joint6" type="revolute">
    <parent link="link5"/>
    <child link="link6"/>
    <origin xyz="0.0000 0.0000 -0.0800" rpy="0.0000 0.0000 0.0000"/>
    <axis xyz="0.000000000000000 0.000000000000000 1.000000000000000"/>
    <limit lower="-6.28319" upper="6.28319" effort="100.0" velocity="1.5"/>
  </joint>
  <joint name="joint_tool0" type="fixed">
    <parent link="link6"/>
    <child link="tool0"/>
    <origin xyz="0.0000 0.0000 0.0000" rpy="0.0000 0.0000 0.0000"/>
  </joint>
</robot>