<?xml version="1.0" ?>
<robot name="GP8L">
  <link name="base_link">
    <visual>
      <origin xyz="-0.0000 -0.0000 -0.0000" rpy="1.5707963267948966 0.0 -1.5707963267948966"/>
      <geometry>
        <mesh filename="package://GP8L/meshes/base_link.stl" scale="0.001 0.001 0.001"/>
      </geometry>
    </visual>
    <collision>
      <origin xyz="-0.0000 -0.0000 -0.0000" rpy="1.5707963267948966 0.0 -1.5707963267948966"/>
      <geometry>
        <mesh filename="package://GP8L/meshes/base_link.stl" scale="0.001 0.001 0.001"/>
      </geometry>
    </collision>
  </link>
  <link name="link1">
    <visual>
      <origin xyz="-0.0000 -0.0000 -0.1650" rpy="1.5707963267948966 0.0 -1.5707963267948966"/>
      <geometry>
        <mesh filename="package://GP8L/meshes/link1.stl" scale="0.001 0.001 0.001"/>
      </geometry>
    </visual>
    <collision>
      <origin xyz="-0.0000 -0.0000 -0.1650" rpy="1.5707963267948966 0.0 -1.5707963267948966"/>
      <geometry>
        <mesh filename="package://GP8L/meshes/link1.stl" scale="0.001 0.001 0.001"/>
      </geometry>
    </collision>
  </link>
  <link name="link2">
    <visual>
      <origin xyz="0.0450 0.1550 -0.4500" rpy="1.5707963267948966 0.0 -1.5707963267948966"/>
      <geometry>
        <mesh filename="package://GP8L/meshes/link2.stl" scale="0.001 0.001 0.001"/>
      </geometry>
    </visual>
    <collision>
      <origin xyz="0.0450 0.1550 -0.4500" rpy="1.5707963267948966 0.0 -1.5707963267948966"/>
      <geometry>
        <mesh filename="package://GP8L/meshes/link2.stl" scale="0.001 0.001 0.001"/>
      </geometry>
    </collision>
  </link>
  <link name="link3">
    <visual>
      <origin xyz="0.0450 0.1550 -1.1640" rpy="1.5707963267948966 0.0 -1.5707963267948966"/>
      <geometry>
        <mesh filename="package://GP8L/meshes/link3.stl" scale="0.001 0.001 0.001"/>
      </geometry>
    </visual>
    <collision>
      <origin xyz="0.0450 0.1550 -1.1640" rpy="1.5707963267948966 0.0 -1.5707963267948966"/>
      <geometry>
        <mesh filename="package://GP8L/meshes/link3.stl" scale="0.001 0.001 0.001"/>
      </geometry>
    </collision>
  </link>
  <link name="link4">
    <visual>
      <origin xyz="-0.0000 0.6265 -1.3640" rpy="1.5707963267948966 0.0 -1.5707963267948966"/>
      <geometry>
        <mesh filename="package://GP8L/meshes/link4.stl" scale="0.001 0.001 0.001"/>
      </geometry>
    </visual>
    <collision>
      <origin xyz="-0.0000 0.6265 -1.3640" rpy="1.5707963267948966 0.0 -1.5707963267948966"/>
      <geometry>
        <mesh filename="package://GP8L/meshes/link4.stl" scale="0.001 0.001 0.001"/>
      </geometry>
    </collision>
  </link>
  <link name="link5">
    <visual>
      <origin xyz="-0.0000 0.8950 -1.3640" rpy="1.5707963267948966 0.0 -1.5707963267948966"/>
      <geometry>
        <mesh filename="package://GP8L/meshes/link5.stl" scale="0.001 0.001 0.001"/>
      </geometry>
    </visual>
    <collision>
      <origin xyz="-0.0000 0.8950 -1.3640" rpy="1.5707963267948966 0.0 -1.5707963267948966"/>
      <geometry>
        <mesh filename="package://GP8L/meshes/link5.stl" scale="0.001 0.001 0.001"/>
      </geometry>
    </collision>
  </link>
  <link name="link6">
    <visual>
      <origin xyz="-0.0000 0.9750 -1.3640" rpy="1.5707963267948966 0.0 -1.5707963267948966"/>
      <geometry>
        <mesh filename="package://GP8L/meshes/link6.stl" scale="0.001 0.001 0.001"/>
      </geometry>
    </visual>
    <collision>
      <origin xyz="-0.0000 0.9750 -1.3640" rpy="1.5707963267948966 0.0 -1.5707963267948966"/>
      <geometry>
        <mesh filename="package://GP8L/meshes/link6.stl" scale="0.001 0.001 0.001"/>
      </geometry>
    </collision>
  </link>
  <link name="spacer">
  </link>
  <link name="tool0">
  </link>
  <joint name="joint1" type="revolute">
    <parent link="base_link"/>
    <child link="link1"/>
    <origin xyz="0.0000 0.0000 0.1650" rpy="0.0000 0.0000 0.0000"/>
    <axis xyz="0.000000000000000 0.000000000000000 1.000000000000000"/>
    <limit lower="-2.96706" upper="2.96706" effort="100.0" velocity="1.5"/>
  </joint>
  <joint name="joint2" type="revolute">
    <parent link="link1"/>
    <child link="link2"/>
    <origin xyz="-0.0450 -0.1550 0.2850" rpy="0.0000 0.0000 0.0000"/>
    <axis xyz="-1.000000000000000 0.000000000000000 0.000000000000000"/>
    <limit lower="-1.57080" upper="2.61799" effort="100.0" velocity="1.5"/>
  </joint>
  <joint name="joint3" type="revolute">
    <parent link="link2"/>
    <child link="link3"/>
    <origin xyz="0.0000 0.0000 0.7140" rpy="0.0000 0.0000 0.0000"/>
    <axis xyz="1.000000000000000 0.000000000000000 0.000000000000000"/>
    <limit lower="-1.48353" upper="2.61799" effort="100.0" velocity="1.5"/>
  </joint>
  <joint name="joint_s" type="fixed">
    <parent link="link3"/>
    <child link="spacer"/>
    <origin xyz="0.0450 -0.2670 0.2000" rpy="0.0000 0.0000 0.0000"/>
  </joint>
  <joint name="joint4" type="revolute">
    <parent link="spacer"/>
    <child link="link4"/>
    <origin xyz="0.0000 -0.2045 0.0000" rpy="0.0000 0.0000 0.0000"/>
    <axis xyz="0.000000000000000 -1.000000000000000 0.000000000000000"/>
    <limit lower="-3.49066" upper="3.49066" effort="100.0" velocity="1.5"/>
  </joint>
  <joint name="joint5" type="revolute">
    <parent link="link4"/>
    <child link="link5"/>
    <origin xyz="0.0000 -0.2685 0.0000" rpy="0.0000 0.0000 0.0000"/>
    <axis xyz="1.000000000000000 0.000000000000000 0.000000000000000"/>
    <limit lower="-2.35619" upper="2.35619" effort="100.0" velocity="1.5"/>
  </joint>
  <joint name="joint6" type="revolute">
    <parent link="link5"/>
    <child link="link6"/>
    <origin xyz="0.0000 -0.0800 0.0000" rpy="0.0000 0.0000 0.0000"/>
    <axis xyz="0.000000000000000 -1.000000000000000 0.000000000000000"/>
    <limit lower="-6.28319" upper="6.28319" effort="100.0" velocity="1.5"/>
  </joint>
  <joint name="joint_tool0" type="fixed">
    <parent link="link6"/>
    <child link="tool0"/>
    <origin xyz="0.0000 0.0000 0.0000" rpy="0.0000 0.0000 0.0000"/>
  </joint>
</robot>