<?xml version="1.0" ?>
<robot name="MPX3500-C00X">
  <link name="base_link">
    <visual>
      <origin xyz="-0.0000 -0.0000 -0.0000" rpy="1.5707963267948966 0.0 -1.5707963267948966"/>
      <geometry>
        <mesh filename="package://MPX3500-C00X/meshes/base_link.stl" scale="0.001 0.001 0.001"/>
      </geometry>
    </visual>
    <collision>
      <origin xyz="-0.0000 -0.0000 -0.0000" rpy="1.5707963267948966 0.0 -1.5707963267948966"/>
      <geometry>
        <mesh filename="package://MPX3500-C00X/meshes/base_link.stl" scale="0.001 0.001 0.001"/>
      </geometry>
    </collision>
  </link>
  <link name="link1">
    <visual>
      <origin xyz="-0.0000 -0.0000 -0.4250" rpy="1.5707963267948966 0.0 -1.5707963267948966"/>
      <geometry>
        <mesh filename="package://MPX3500-C00X/meshes/link1.stl" scale="0.001 0.001 0.001"/>
      </geometry>
    </visual>
    <collision>
      <origin xyz="-0.0000 -0.0000 -0.4250" rpy="1.5707963267948966 0.0 -1.5707963267948966"/>
      <geometry>
        <mesh filename="package://MPX3500-C00X/meshes/link1.stl" scale="0.001 0.001 0.001"/>
      </geometry>
    </collision>
  </link>
  <link name="link2">
    <visual>
      <origin xyz="-0.0000 -0.0000 -0.8000" rpy="1.5707963267948966 0.0 -1.5707963267948966"/>
      <geometry>
        <mesh filename="package://MPX3500-C00X/meshes/link2.stl" scale="0.001 0.001 0.001"/>
      </geometry>
    </visual>
    <collision>
      <origin xyz="-0.0000 -0.0000 -0.8000" rpy="1.5707963267948966 0.0 -1.5707963267948966"/>
      <geometry>
        <mesh filename="package://MPX3500-C00X/meshes/link2.stl" scale="0.001 0.001 0.001"/>
      </geometry>
    </collision>
  </link>
  <link name="link3">
    <visual>
      <origin xyz="-0.0000 -0.0000 -2.1000" rpy="1.5707963267948966 0.0 -1.5707963267948966"/>
      <geometry>
        <mesh filename="package://MPX3500-C00X/meshes/link3.stl" scale="0.001 0.001 0.001"/>
      </geometry>
    </visual>
    <collision>
      <origin xyz="-0.0000 -0.0000 -2.1000" rpy="1.5707963267948966 0.0 -1.5707963267948966"/>
      <geometry>
        <mesh filename="package://MPX3500-C00X/meshes/link3.stl" scale="0.001 0.001 0.001"/>
      </geometry>
    </collision>
  </link>
  <link name="link4">
    <visual>
      <origin xyz="-0.0000 1.4000 -2.1000" rpy="1.5707963267948966 0.0 -1.5707963267948966"/>
      <geometry>
        <mesh filename="package://MPX3500-C00X/meshes/link4.stl" scale="0.001 0.001 0.001"/>
      </geometry>
    </visual>
    <collision>
      <origin xyz="-0.0000 1.4000 -2.1000" rpy="1.5707963267948966 0.0 -1.5707963267948966"/>
      <geometry>
        <mesh filename="package://MPX3500-C00X/meshes/link4.stl" scale="0.001 0.001 0.001"/>
      </geometry>
    </collision>
  </link>
  <link name="link5">
    <visual>
      <origin xyz="-0.0000 1.4000 -2.1000" rpy="1.5707963267948966 0.0 -1.5707963267948966"/>
      <geometry>
        <mesh filename="package://MPX3500-C00X/meshes/link5.stl" scale="0.001 0.001 0.001"/>
      </geometry>
    </visual>
    <collision>
      <origin xyz="-0.0000 1.4000 -2.1000" rpy="1.5707963267948966 0.0 -1.5707963267948966"/>
      <geometry>
        <mesh filename="package://MPX3500-C00X/meshes/link5.stl" scale="0.001 0.001 0.001"/>
      </geometry>
    </collision>
  </link>
  <link name="link6">
    <visual>
      <origin xyz="-0.0000 1.5800 -2.0000" rpy="1.5707963267948966 0.0 -1.5707963267948966"/>
      <geometry>
        <mesh filename="package://MPX3500-C00X/meshes/link6.stl" scale="0.001 0.001 0.001"/>
      </geometry>
    </visual>
    <collision>
      <origin xyz="-0.0000 1.5800 -2.0000" rpy="1.5707963267948966 0.0 -1.5707963267948966"/>
      <geometry>
        <mesh filename="package://MPX3500-C00X/meshes/link6.stl" scale="0.001 0.001 0.001"/>
      </geometry>
    </collision>
  </link>
  <link name="tool0">
  </link>
  <joint name="joint1" type="revolute">
    <parent link="base_link"/>
    <child link="link1"/>
    <origin xyz="0.0000 0.0000 0.4250" rpy="0.0000 0.0000 0.0000"/>
    <axis xyz="0.000000000000000 0.000000000000000 1.000000000000000"/>
    <limit lower="-2.61799" upper="2.61799" effort="100.0" velocity="1.5"/>
  </joint>
  <joint name="joint2" type="revolute">
    <parent link="link1"/>
    <child link="link2"/>
    <origin xyz="0.0000 0.0000 0.3750" rpy="0.0000 0.0000 0.0000"/>
    <axis xyz="1.000000000000000 0.000000000000000 0.000000000000000"/>
    <limit lower="-1.13446" upper="2.44346" effort="100.0" velocity="1.5"/>
  </joint>
  <joint name="joint3" type="revolute">
    <parent link="link2"/>
    <child link="link3"/>
    <origin xyz="0.0000 0.0000 1.3000" rpy="0.0000 0.0000 0.0000"/>
    <axis xyz="-1.000000000000000 0.000000000000000 0.000000000000000"/>
    <limit lower="-1.13446" upper="1.57080" effort="100.0" velocity="1.5"/>
  </joint>
  <joint name="joint4" type="revolute">
    <parent link="link3"/>
    <child link="link4"/>
    <origin xyz="0.0000 -1.4000 0.0000" rpy="0.0000 0.0000 0.0000"/>
    <axis xyz="0.000000000000000 -1.000000000000000 0.000000000000000"/>
    <limit lower="-12.56637" upper="12.56637" effort="100.0" velocity="1.5"/>
  </joint>
  <joint name="joint5" type="revolute">
    <parent link="link4"/>
    <child link="link5"/>
    <origin xyz="0.0000 0.0000 0.0000" rpy="0.0000 0.0000 0.0000"/>
    <axis xyz="0.000000000000000 -0.500000000000000 -0.866025404000000"/>
    <limit lower="-12.56637" upper="12.56637" effort="100.0" velocity="1.5"/>
  </joint>
  <joint name="joint6" type="revolute">
    <parent link="link5"/>
    <child link="link6"/>
    <origin xyz="0.0000 -0.1800 -0.1000" rpy="0.0000 0.0000 0.0000"/>
    <axis xyz="0.000000000000000 -1.000000000000000 0.000000000000000"/>
    <limit lower="-12.56637" upper="12.56637" effort="100.0" velocity="1.5"/>
  </joint>
  <joint name="joint_tool0" type="fixed">
    <parent link="link6"/>
    <child link="tool0"/>
    <origin xyz="0.0000 0.0000 0.0000" rpy="0.0000 0.0000 0.0000"/>
  </joint>
</robot>