<?xml version="1.0" ?>
<robot name="GP50">
  <link name="base_link">
    <visual>
      <origin xyz="-0.0000 -0.0000 -0.0000" rpy="1.5707963267948966 0.0 -1.5707963267948966"/>
      <geometry>
        <mesh filename="package://GP50/meshes/base_link.stl" scale="0.001 0.001 0.001"/>
      </geometry>
    </visual>
    <collision>
      <origin xyz="-0.0000 -0.0000 -0.0000" rpy="1.5707963267948966 0.0 -1.5707963267948966"/>
      <geometry>
        <mesh filename="package://GP50/meshes/base_link.stl" scale="0.001 0.001 0.001"/>
      </geometry>
    </collision>
  </link>
  <link name="link1">
    <visual>
      <origin xyz="-0.0000 -0.0000 -0.2590" rpy="1.5707963267948966 0.0 -1.5707963267948966"/>
      <geometry>
        <mesh filename="package://GP50/meshes/link1.stl" scale="0.001 0.001 0.001"/>
      </geometry>
    </visual>
    <collision>
      <origin xyz="-0.0000 -0.0000 -0.2590" rpy="1.5707963267948966 0.0 -1.5707963267948966"/>
      <geometry>
        <mesh filename="package://GP50/meshes/link1.stl" scale="0.001 0.001 0.001"/>
      </geometry>
    </collision>
  </link>
  <link name="link2">
    <visual>
      <origin xyz="-0.0000 0.1450 -0.5400" rpy="1.5707963267948966 0.0 -1.5707963267948966"/>
      <geometry>
        <mesh filename="package://GP50/meshes/link2.stl" scale="0.001 0.001 0.001"/>
      </geometry>
    </visual>
    <collision>
      <origin xyz="-0.0000 0.1450 -0.5400" rpy="1.5707963267948966 0.0 -1.5707963267948966"/>
      <geometry>
        <mesh filename="package://GP50/meshes/link2.stl" scale="0.001 0.001 0.001"/>
      </geometry>
    </collision>
  </link>
  <link name="link3">
    <visual>
      <origin xyz="-0.0000 0.1450 -1.6200" rpy="1.5707963267948966 0.0 -1.5707963267948966"/>
      <geometry>
        <mesh filename="package://GP50/meshes/link3.stl" scale="0.001 0.001 0.001"/>
      </geometry>
    </visual>
    <collision>
      <origin xyz="-0.0000 0.1450 -1.6200" rpy="1.5707963267948966 0.0 -1.5707963267948966"/>
      <geometry>
        <mesh filename="package://GP50/meshes/link3.stl" scale="0.001 0.001 0.001"/>
      </geometry>
    </collision>
  </link>
  <link name="link4">
    <visual>
      <origin xyz="-0.0000 1.0250 -1.6200" rpy="1.5707963267948966 0.0 -1.5707963267948966"/>
      <geometry>
        <mesh filename="package://GP50/meshes/link4.stl" scale="0.001 0.001 0.001"/>
      </geometry>
    </visual>
    <collision>
      <origin xyz="-0.0000 1.0250 -1.6200" rpy="1.5707963267948966 0.0 -1.5707963267948966"/>
      <geometry>
        <mesh filename="package://GP50/meshes/link4.stl" scale="0.001 0.001 0.001"/>
      </geometry>
    </collision>
  </link>
  <link name="link5">
    <visual>
      <origin xyz="-0.0000 1.0250 -1.6200" rpy="1.5707963267948966 0.0 -1.5707963267948966"/>
      <geometry>
        <mesh filename="package://GP50/meshes/link5.stl" scale="0.001 0.001 0.001"/>
      </geometry>
    </visual>
    <collision>
      <origin xyz="-0.0000 1.0250 -1.6200" rpy="1.5707963267948966 0.0 -1.5707963267948966"/>
      <geometry>
        <mesh filename="package://GP50/meshes/link5.stl" scale="0.001 0.001 0.001"/>
      </geometry>
    </collision>
  </link>
  <link name="link6">
    <visual>
      <origin xyz="-0.0000 1.2000 -1.6200" rpy="1.5707963267948966 0.0 -1.5707963267948966"/>
      <geometry>
        <mesh filename="package://GP50/meshes/link6.stl" scale="0.001 0.001 0.001"/>
      </geometry>
    </visual>
    <collision>
      <origin xyz="-0.0000 1.2000 -1.6200" rpy="1.5707963267948966 0.0 -1.5707963267948966"/>
      <geometry>
        <mesh filename="package://GP50/meshes/link6.stl" scale="0.001 0.001 0.001"/>
      </geometry>
    </collision>
  </link>
  <link name="tool0">
  </link>
  <joint name="joint1" type="revolute">
    <parent link="base_link"/>
    <child link="link1"/>
    <origin xyz="0.0000 0.0000 0.2590" rpy="0.0000 0.0000 0.0000"/>
    <axis xyz="0.000000000000000 0.000000000000000 1.000000000000000"/>
    <limit lower="-3.14159" upper="3.14159" effort="100.0" velocity="1.5"/>
  </joint>
  <joint name="joint2" type="revolute">
    <parent link="link1"/>
    <child link="link2"/>
    <origin xyz="0.0000 -0.1450 0.2810" rpy="0.0000 0.0000 0.0000"/>
    <axis xyz="-1.000000000000000 0.000000000000000 0.000000000000000"/>
    <limit lower="-1.57080" upper="2.35619" effort="100.0" velocity="1.5"/>
  </joint>
  <joint name="joint3" type="revolute">
    <parent link="link2"/>
    <child link="link3"/>
    <origin xyz="0.0000 0.0000 1.0800" rpy="0.0000 0.0000 0.0000"/>
    <axis xyz="1.000000000000000 0.000000000000000 0.000000000000000"/>
    <limit lower="-1.39626" upper="3.59538" effort="100.0" velocity="1.5"/>
  </joint>
  <joint name="joint4" type="revolute">
    <parent link="link3"/>
    <child link="link4"/>
    <origin xyz="0.0000 -0.8800 0.0000" rpy="0.0000 0.0000 0.0000"/>
    <axis xyz="0.000000000000000 -1.000000000000000 0.000000000000000"/>
    <limit lower="-6.28319" upper="6.28319" effort="100.0" velocity="1.5"/>
  </joint>
  <joint name="joint5" type="revolute">
    <parent link="link4"/>
    <child link="link5"/>
    <origin xyz="0.0000 0.0000 0.0000" rpy="0.0000 0.0000 0.0000"/>
    <axis xyz="1.000000000000000 0.000000000000000 0.000000000000000"/>
    <limit lower="-2.18166" upper="2.18166" effort="100.0" velocity="1.5"/>
  </joint>
  <joint name="joint6" type="revolute">
    <parent link="link5"/>
    <child link="link6"/>
    <origin xyz="0.0000 -0.1750 0.0000" rpy="0.0000 0.0000 0.0000"/>
    <axis xyz="0.000000000000000 -1.000000000000000 0.000000000000000"/>
    <limit lower="-6.28319" upper="6.28319" effort="100.0" velocity="1.5"/>
  </joint>
  <joint name="joint_tool0" type="fixed">
    <parent link="link6"/>
    <child link="tool0"/>
    <origin xyz="0.0000 0.0000 0.0000" rpy="0.0000 0.0000 0.0000"/>
  </joint>
</robot>